<?xml version="1.0" encoding="UTF-8"?>
<testsuite errors="14" failures="0" file="utils_tests.py" name="utils_tests.TestLuhnVerified-20200913162834" skipped="0" tests="14" time="0.104" timestamp="2020-09-13T16:28:34">
	<testcase classname="utils_tests.TestLuhnVerified" name="test_luhn_invalid_card_number_at_maximum" time="0.079" timestamp="2020-09-13T16:28:34">
		<error message="module 'utils' has no attribute 'luhn_verified'" type="AttributeError">
<![CDATA[Traceback (most recent call last):
  File "/usr/lib/python3.6/unittest/case.py", line 59, in testPartExecutor
    yield
  File "/usr/lib/python3.6/unittest/case.py", line 605, in run
    testMethod()
  File "/home/student/Documents/cs3280project1/src/unittest/python/utils_tests.py", line 169, in test_luhn_invalid_card_number_at_maximum
    is_luhn_verified = utils.luhn_verified('1234567890123456789')
AttributeError: module 'utils' has no attribute 'luhn_verified'
]]>		</error>
	</testcase>
	<testcase classname="utils_tests.TestLuhnVerified" name="test_luhn_invalid_card_number_at_minimum" time="0.002" timestamp="2020-09-13T16:28:34">
		<error message="module 'utils' has no attribute 'luhn_verified'" type="AttributeError">
<![CDATA[Traceback (most recent call last):
  File "/usr/lib/python3.6/unittest/case.py", line 59, in testPartExecutor
    yield
  File "/usr/lib/python3.6/unittest/case.py", line 605, in run
    testMethod()
  File "/home/student/Documents/cs3280project1/src/unittest/python/utils_tests.py", line 121, in test_luhn_invalid_card_number_at_minimum
    is_luhn_verified = utils.luhn_verified('5038186303745')
AttributeError: module 'utils' has no attribute 'luhn_verified'
]]>		</error>
	</testcase>
	<testcase classname="utils_tests.TestLuhnVerified" name="test_luhn_invalid_card_number_between_minimum_and_maximum" time="0.002" timestamp="2020-09-13T16:28:34">
		<error message="module 'utils' has no attribute 'luhn_verified'" type="AttributeError">
<![CDATA[Traceback (most recent call last):
  File "/usr/lib/python3.6/unittest/case.py", line 59, in testPartExecutor
    yield
  File "/usr/lib/python3.6/unittest/case.py", line 605, in run
    testMethod()
  File "/home/student/Documents/cs3280project1/src/unittest/python/utils_tests.py", line 145, in test_luhn_invalid_card_number_between_minimum_and_maximum
    is_luhn_verified = utils.luhn_verified('1234567890123456')
AttributeError: module 'utils' has no attribute 'luhn_verified'
]]>		</error>
	</testcase>
	<testcase classname="utils_tests.TestLuhnVerified" name="test_luhn_invalid_card_number_grouped_by_dashes" time="0.002" timestamp="2020-09-13T16:28:34">
		<error message="module 'utils' has no attribute 'luhn_verified'" type="AttributeError">
<![CDATA[Traceback (most recent call last):
  File "/usr/lib/python3.6/unittest/case.py", line 59, in testPartExecutor
    yield
  File "/usr/lib/python3.6/unittest/case.py", line 605, in run
    testMethod()
  File "/home/student/Documents/cs3280project1/src/unittest/python/utils_tests.py", line 193, in test_luhn_invalid_card_number_grouped_by_dashes
    is_luhn_verified = utils.luhn_verified('1234-5678-9012-3455')
AttributeError: module 'utils' has no attribute 'luhn_verified'
]]>		</error>
	</testcase>
	<testcase classname="utils_tests.TestLuhnVerified" name="test_luhn_invalid_card_number_grouped_by_spaces" time="0.002" timestamp="2020-09-13T16:28:34">
		<error message="module 'utils' has no attribute 'luhn_verified'" type="AttributeError">
<![CDATA[Traceback (most recent call last):
  File "/usr/lib/python3.6/unittest/case.py", line 59, in testPartExecutor
    yield
  File "/usr/lib/python3.6/unittest/case.py", line 605, in run
    testMethod()
  File "/home/student/Documents/cs3280project1/src/unittest/python/utils_tests.py", line 181, in test_luhn_invalid_card_number_grouped_by_spaces
    is_luhn_verified = utils.luhn_verified('1234 5678 9012 3455')
AttributeError: module 'utils' has no attribute 'luhn_verified'
]]>		</error>
	</testcase>
	<testcase classname="utils_tests.TestLuhnVerified" name="test_luhn_invalid_card_number_one_above_minimum" time="0.002" timestamp="2020-09-13T16:28:34">
		<error message="module 'utils' has no attribute 'luhn_verified'" type="AttributeError">
<![CDATA[Traceback (most recent call last):
  File "/usr/lib/python3.6/unittest/case.py", line 59, in testPartExecutor
    yield
  File "/usr/lib/python3.6/unittest/case.py", line 605, in run
    testMethod()
  File "/home/student/Documents/cs3280project1/src/unittest/python/utils_tests.py", line 133, in test_luhn_invalid_card_number_one_above_minimum
    is_luhn_verified = utils.luhn_verified('50381863037455')
AttributeError: module 'utils' has no attribute 'luhn_verified'
]]>		</error>
	</testcase>
	<testcase classname="utils_tests.TestLuhnVerified" name="test_luhn_invalid_card_number_one_below_maximum" time="0.002" timestamp="2020-09-13T16:28:34">
		<error message="module 'utils' has no attribute 'luhn_verified'" type="AttributeError">
<![CDATA[Traceback (most recent call last):
  File "/usr/lib/python3.6/unittest/case.py", line 59, in testPartExecutor
    yield
  File "/usr/lib/python3.6/unittest/case.py", line 605, in run
    testMethod()
  File "/home/student/Documents/cs3280project1/src/unittest/python/utils_tests.py", line 157, in test_luhn_invalid_card_number_one_below_maximum
    is_luhn_verified = utils.luhn_verified('123456789012345678')
AttributeError: module 'utils' has no attribute 'luhn_verified'
]]>		</error>
	</testcase>
	<testcase classname="utils_tests.TestLuhnVerified" name="test_luhn_valid_card_number_at_maximum" time="0.002" timestamp="2020-09-13T16:28:34">
		<error message="module 'utils' has no attribute 'luhn_verified'" type="AttributeError">
<![CDATA[Traceback (most recent call last):
  File "/usr/lib/python3.6/unittest/case.py", line 59, in testPartExecutor
    yield
  File "/usr/lib/python3.6/unittest/case.py", line 605, in run
    testMethod()
  File "/home/student/Documents/cs3280project1/src/unittest/python/utils_tests.py", line 163, in test_luhn_valid_card_number_at_maximum
    is_luhn_verified = utils.luhn_verified('1234567890123456785')
AttributeError: module 'utils' has no attribute 'luhn_verified'
]]>		</error>
	</testcase>
	<testcase classname="utils_tests.TestLuhnVerified" name="test_luhn_valid_card_number_at_minimum" time="0.002" timestamp="2020-09-13T16:28:34">
		<error message="module 'utils' has no attribute 'luhn_verified'" type="AttributeError">
<![CDATA[Traceback (most recent call last):
  File "/usr/lib/python3.6/unittest/case.py", line 59, in testPartExecutor
    yield
  File "/usr/lib/python3.6/unittest/case.py", line 605, in run
    testMethod()
  File "/home/student/Documents/cs3280project1/src/unittest/python/utils_tests.py", line 115, in test_luhn_valid_card_number_at_minimum
    is_luhn_verified = utils.luhn_verified('5038186303744')
AttributeError: module 'utils' has no attribute 'luhn_verified'
]]>		</error>
	</testcase>
	<testcase classname="utils_tests.TestLuhnVerified" name="test_luhn_valid_card_number_between_minimum_and_maximum" time="0.002" timestamp="2020-09-13T16:28:34">
		<error message="module 'utils' has no attribute 'luhn_verified'" type="AttributeError">
<![CDATA[Traceback (most recent call last):
  File "/usr/lib/python3.6/unittest/case.py", line 59, in testPartExecutor
    yield
  File "/usr/lib/python3.6/unittest/case.py", line 605, in run
    testMethod()
  File "/home/student/Documents/cs3280project1/src/unittest/python/utils_tests.py", line 139, in test_luhn_valid_card_number_between_minimum_and_maximum
    is_luhn_verified = utils.luhn_verified('1234567890123452')
AttributeError: module 'utils' has no attribute 'luhn_verified'
]]>		</error>
	</testcase>
	<testcase classname="utils_tests.TestLuhnVerified" name="test_luhn_valid_card_number_grouped_by_dashes" time="0.002" timestamp="2020-09-13T16:28:34">
		<error message="module 'utils' has no attribute 'luhn_verified'" type="AttributeError">
<![CDATA[Traceback (most recent call last):
  File "/usr/lib/python3.6/unittest/case.py", line 59, in testPartExecutor
    yield
  File "/usr/lib/python3.6/unittest/case.py", line 605, in run
    testMethod()
  File "/home/student/Documents/cs3280project1/src/unittest/python/utils_tests.py", line 187, in test_luhn_valid_card_number_grouped_by_dashes
    is_luhn_verified = utils.luhn_verified('1234-5678-9012-3452')
AttributeError: module 'utils' has no attribute 'luhn_verified'
]]>		</error>
	</testcase>
	<testcase classname="utils_tests.TestLuhnVerified" name="test_luhn_valid_card_number_grouped_by_spaces" time="0.002" timestamp="2020-09-13T16:28:34">
		<error message="module 'utils' has no attribute 'luhn_verified'" type="AttributeError">
<![CDATA[Traceback (most recent call last):
  File "/usr/lib/python3.6/unittest/case.py", line 59, in testPartExecutor
    yield
  File "/usr/lib/python3.6/unittest/case.py", line 605, in run
    testMethod()
  File "/home/student/Documents/cs3280project1/src/unittest/python/utils_tests.py", line 175, in test_luhn_valid_card_number_grouped_by_spaces
    is_luhn_verified = utils.luhn_verified('1234 5678 9012 3452')
AttributeError: module 'utils' has no attribute 'luhn_verified'
]]>		</error>
	</testcase>
	<testcase classname="utils_tests.TestLuhnVerified" name="test_luhn_valid_card_number_one_above_minimum" time="0.002" timestamp="2020-09-13T16:28:34">
		<error message="module 'utils' has no attribute 'luhn_verified'" type="AttributeError">
<![CDATA[Traceback (most recent call last):
  File "/usr/lib/python3.6/unittest/case.py", line 59, in testPartExecutor
    yield
  File "/usr/lib/python3.6/unittest/case.py", line 605, in run
    testMethod()
  File "/home/student/Documents/cs3280project1/src/unittest/python/utils_tests.py", line 127, in test_luhn_valid_card_number_one_above_minimum
    is_luhn_verified = utils.luhn_verified('50381863037456')
AttributeError: module 'utils' has no attribute 'luhn_verified'
]]>		</error>
	</testcase>
	<testcase classname="utils_tests.TestLuhnVerified" name="test_luhn_valid_card_number_one_below_maximum" time="0.002" timestamp="2020-09-13T16:28:34">
		<error message="module 'utils' has no attribute 'luhn_verified'" type="AttributeError">
<![CDATA[Traceback (most recent call last):
  File "/usr/lib/python3.6/unittest/case.py", line 59, in testPartExecutor
    yield
  File "/usr/lib/python3.6/unittest/case.py", line 605, in run
    testMethod()
  File "/home/student/Documents/cs3280project1/src/unittest/python/utils_tests.py", line 151, in test_luhn_valid_card_number_one_below_maximum
    is_luhn_verified = utils.luhn_verified('123456789012345671')
AttributeError: module 'utils' has no attribute 'luhn_verified'
]]>		</error>
	</testcase>
</testsuite>
